{"version":3,"sources":["app.js"],"names":["doException","Error","noException","callException","type","console","log","main","e"],"mappings":"AAAA,SAASA,WAAT,GAAuB;AACrB,QAAM,IAAIC,KAAJ,CAAU,UAAV,CAAN;AACD;;AAED,SAASC,WAAT,GAAuB;AACrB,SAAO,IAAP;AACD;;AAED,SAASC,aAAT,CAAuBC,IAAvB,EAA6B;AAC3B,MAAIA,IAAI,KAAK,IAAb,EAAmB;AACjBJ,IAAAA,WAAW;AACZ,GAFD,MAEO;AACL,QAAIE,WAAW,OAAO,KAAtB,EAA6B;AAC3BG,MAAAA,OAAO,CAACC,GAAR,CAAY,MAAZ;AACD;AACF;AACF;;AAED,SAASC,IAAT,GAAgB;AACd;AACF;AACA;AACA;AACA;AACA;AACE,MAAI;AACFJ,IAAAA,aAAa,CAAC,IAAD,CAAb;AACD,GAFD,CAEE,OAAOK,CAAP,EAAU;AACVH,IAAAA,OAAO,CAACC,GAAR,CAAYE,CAAZ;AACD,GAJD,SAIU;AACRH,IAAAA,OAAO,CAACC,GAAR,CAAY,MAAZ;AACD;AACF;;AAEDC,IAAI","file":"app.c328ef1a.js","sourceRoot":"..","sourcesContent":["function doException() {\n  throw new Error(\"와우! 오류야!\");\n}\n\nfunction noException() {\n  return true;\n}\n\nfunction callException(type) {\n  if (type === \"do\") {\n    doException();\n  } else {\n    if (noException() === false) {\n      console.log(\"오류처리\");\n    }\n  }\n}\n\nfunction main() {\n  /*\n  예외가 발생하지 않으면 try 구문 실행 후 finally 구문 실행\n  예외가 발생하면 catch 구문 실행 후 finally 구문 실행\n  catch에는 throw로 던저진 error객체를 인자로 받을 수 있다.\n  finally는 에러가 나던 안나던 실행할 코드가 있을 경우 작성! 생략 가능\n  */\n  try {\n    callException(\"do\");\n  } catch (e) {\n    console.log(e);\n  } finally {\n    console.log(\"done\");\n  }\n}\n\nmain();\n"]}